<mujoco model="nadia">
  <compiler angle="radian" meshdir="../../" convexhull="true"/>

  <default>
    <default class="collision">
        <default class="foot">
          <geom pos="0 0 0"  priority="1" condim="6"
            friction="1 0.02 0.01" type="mesh" mesh="foot"/>
        </default>
    </default>
  </default>

  <asset>
    <mesh name="pelvis" file="nadia_V16_description/meshes/pelvis.obj"/>
    <mesh name="left_hip_yaw" file="nadia_V16_description/meshes/left_hip_yaw.obj"/>
    <mesh name="right_hip_yaw" file="nadia_V16_description/meshes/right_hip_yaw.obj"/>
    <mesh name="left_hip_roll" file="nadia_V16_description/meshes/left_hip_roll.obj"/>
    <mesh name="right_hip_roll" file="nadia_V16_description/meshes/right_hip_roll.obj"/>
    <mesh name="left_thigh" file="nadia_V16_description/meshes/left_thigh.obj"/>
    <mesh name="right_thigh" file="nadia_V16_description/meshes/right_thigh.obj"/>
    <mesh name="left_shin" file="nadia_V16_description/meshes/left_shin.obj"/>
    <mesh name="right_shin" file="nadia_V16_description/meshes/right_shin.obj"/>
    <mesh name="ankle" file="nadia_V16_description/meshes/ankle.obj"/>
    <mesh name="foot" file="nadia_V16_description/meshes/foot.obj"/>
    <mesh name="spine_yaw" file="nadia_V16_description/meshes/spine_yaw.obj"/>
    <mesh name="spine_roll" file="nadia_V16_description/meshes/spine_roll.obj"/>
    <mesh name="torso_cycloidmounts" file="nadia_V16_description/meshes/torso_cycloidmounts.obj"/>
    <mesh name="LEFT_SHOULDER_PITCH_LINK" file="nadia_V17_description/meshes/cycloidal_arm/LEFT_SHOULDER_PITCH_LINK.obj"/>
    <mesh name="LEFT_SHOULDER_ROLL_LINK" file="nadia_V17_description/meshes/cycloidal_arm/LEFT_SHOULDER_ROLL_LINK.obj"/>
    <mesh name="LEFT_SHOULDER_YAW_LINK" file="nadia_V17_description/meshes/cycloidal_arm/LEFT_SHOULDER_YAW_LINK.obj"/>
    <mesh name="LEFT_ELBOW_PITCH_LINK_413mm_LENGTH" file="nadia_V17_description/meshes/cycloidal_arm/LEFT_ELBOW_PITCH_LINK_413mm_LENGTH.obj"/>
    <mesh name="RIGHT_SHOULDER_PITCH_LINK" file="nadia_V17_description/meshes/cycloidal_arm/RIGHT_SHOULDER_PITCH_LINK.obj"/>
    <mesh name="RIGHT_SHOULDER_ROLL_LINK" file="nadia_V17_description/meshes/cycloidal_arm/RIGHT_SHOULDER_ROLL_LINK.obj"/>
    <mesh name="RIGHT_SHOULDER_YAW_LINK" file="nadia_V17_description/meshes/cycloidal_arm/RIGHT_SHOULDER_YAW_LINK.obj"/>
    <mesh name="RIGHT_ELBOW_PITCH_LINK_413mm_LENGTH" file="nadia_V17_description/meshes/cycloidal_arm/RIGHT_ELBOW_PITCH_LINK_413mm_LENGTH.obj"/>
  </asset>

  <worldbody>
    <body name="PELVIS_LINK">
      <inertial pos="0.0207309 2.023e-05 -0.0309812" quat="0.505264 0.505319 -0.494622 0.494682" mass="19.0917" diaginertia="0.112008 0.0941919 0.0416"/>
      <joint name="pelvis" type="free" limited="false" actuatorfrclimited="false"/>
      <geom type="mesh" contype="0" conaffinity="0" group="1" density="0" mesh="pelvis"/>
      <body name="LEFT_HIP_YAW_LINK" pos="0 0.115 -0.07185">
        <inertial pos="-0.00629727 0.00606893 -0.0397184" quat="0.251371 0.524945 -0.42305 0.694459" mass="1.814" diaginertia="0.00579375 0.00495923 0.00381893"/>
        <joint name="LEFT_HIP_Z" pos="0 0 0" axis="0 0 -1" range="-0.7854 0.7854" actuatorfrcrange="-1000 1000" damping="0.05"/>
        <geom type="mesh" contype="0" conaffinity="0" group="1" density="0" mesh="left_hip_yaw"/>
        <body name="LEFT_HIP_ROLL_LINK" pos="0.035 0.015 -0.04975">
          <inertial pos="-0.0132704 0.00316985 -0.054" quat="0.698747 -0.172124 -0.207716 0.662555" mass="0.762" diaginertia="0.00138167 0.00124217 0.000448147"/>
          <joint name="LEFT_HIP_X" pos="0 0 0" axis="1 0 0" range="-0.5236 1.0472" actuatorfrcrange="-1000 1000" damping="0.05"/>
          <geom type="mesh" contype="0" conaffinity="0" group="1" density="0" mesh="left_hip_roll"/>
          <body name="LEFT_THIGH_LINK" pos="0 0 -0.079068">
            <inertial pos="-0.00093749 0.0113451 -0.178631" quat="0.688421 -0.0440295 -0.0544038 0.721927" mass="10.953" diaginertia="0.17406 0.164387 0.0505798"/>
            <joint name="LEFT_HIP_Y" pos="0 0 0" axis="0 1 0" range="-1.57 0.314" actuatorfrcrange="-1000 1000" damping="0.05"/>
            <geom type="mesh" contype="0" conaffinity="0" group="1" density="0" mesh="left_thigh"/>
            <body name="LEFT_SHIN_LINK" pos="0 0 -0.38">
              <inertial pos="-0.0184149 0.00228086 -0.220542" quat="0.998551 -0.0112323 0.0520477 -0.00785529" mass="5.42" diaginertia="0.0650028 0.0583193 0.0130157"/>
              <joint name="LEFT_KNEE_Y" pos="0 0 0" axis="0 1 0" range="0 2.62" actuatorfrcrange="-350 350" damping="0.05"/>
              <geom type="mesh" contype="0" conaffinity="0" group="1" density="0" mesh="left_shin"/>
              <body name="LEFT_ANKLE_LINK" pos="-0.00830222 0 -0.402139">
                <inertial pos="-0.00072338 -6.619e-05 -0.00399965" quat="0.496787 0.496661 -0.503078 0.503432" mass="0.56" diaginertia="0.000645032 0.000458968 0.000336"/>
                <joint name="LEFT_ANKLE_Y" pos="0 0 0" axis="0 1 0" range="-1.0472 0.698132" actuatorfrcrange="-1000 1000" damping="0.05"/>
                <geom type="mesh" contype="0" conaffinity="0" group="1" density="0" mesh="ankle"/>
                <body name="LEFT_FOOT_LINK" pos="0 0 -0.01">
                  <inertial pos="0.0307545 7.807e-05 -0.0438247" quat="0.436273 0.55545 0.558752 0.434668" mass="1.75" diaginertia="0.00955766 0.00916707 0.00309615"/>
                  <joint name="LEFT_ANKLE_X" pos="0 0 0" axis="1 0 0" range="-0.436332 0.436332" actuatorfrcrange="-1000 1000" damping="0.05"/>
                  <geom type="mesh" contype="0" conaffinity="0" group="1" density="0" mesh="foot"/>
                  <geom name="LEFT" class="foot"/>
                </body>
              </body>
            </body>
          </body>
        </body>
      </body>
      <body name="RIGHT_HIP_YAW_LINK" pos="0 -0.115 -0.07185">
        <inertial pos="-0.00629727 -0.00606893 -0.0397184" quat="0.524945 0.251371 -0.694459 0.42305" mass="1.814" diaginertia="0.00579375 0.00495923 0.00381893"/>
        <joint name="RIGHT_HIP_Z" pos="0 0 0" axis="0 0 -1" range="-0.7854 0.7854" actuatorfrcrange="-1000 1000" damping="0.05"/>
        <geom type="mesh" contype="0" conaffinity="0" group="1" density="0" mesh="right_hip_yaw"/>
        <body name="RIGHT_HIP_ROLL_LINK" pos="0.035 -0.015 -0.04975">
          <inertial pos="-0.0132704 -0.00316985 -0.054" quat="0.662555 -0.207716 -0.172124 0.698747" mass="0.762" diaginertia="0.00138167 0.00124217 0.000448147"/>
          <joint name="RIGHT_HIP_X" pos="0 0 0" axis="1 0 0" range="-1.0472 0.5236" actuatorfrcrange="-1000 1000" damping="0.05"/>
          <geom type="mesh" contype="0" conaffinity="0" group="1" density="0" mesh="right_hip_roll"/>
          <body name="RIGHT_THIGH_LINK" pos="0 0 -0.079068">
            <inertial pos="-0.00093749 -0.0113451 -0.178631" quat="0.721927 -0.0544038 -0.0440295 0.688421" mass="10.953" diaginertia="0.17406 0.164387 0.0505798"/>
            <joint name="RIGHT_HIP_Y" pos="0 0 0" axis="0 1 0" range="-1.57 0.314" actuatorfrcrange="-1000 1000" damping="0.05"/>
            <geom type="mesh" contype="0" conaffinity="0" group="1" density="0" mesh="right_thigh"/>
            <body name="RIGHT_SHIN_LINK" pos="0 0 -0.38">
              <inertial pos="-0.0183705 -0.00241134 -0.219913" quat="0.998556 0.0105807 0.0521445 0.00740775" mass="5.42" diaginertia="0.06501 0.0583171 0.0130161"/>
              <joint name="RIGHT_KNEE_Y" pos="0 0 0" axis="0 1 0" range="0 2.62" actuatorfrcrange="-350 350" damping="0.05"/>
              <geom type="mesh" contype="0" conaffinity="0" group="1" density="0" mesh="right_shin"/>
              <body name="RIGHT_ANKLE_LINK" pos="-0.00830222 0 -0.402139">
                <inertial pos="-0.00072338 6.619e-05 -0.00399965" quat="0.496661 0.496787 -0.503432 0.503078" mass="0.56" diaginertia="0.000645032 0.000458968 0.000336"/>
                <joint name="RIGHT_ANKLE_Y" pos="0 0 0" axis="0 1 0" range="-1.0472 0.698132" actuatorfrcrange="-1000 1000" damping="0.05"/>
                <geom type="mesh" contype="0" conaffinity="0" group="1" density="0" mesh="ankle"/>
                <body name="RIGHT_FOOT_LINK" pos="0 0 -0.01">
                  <inertial pos="0.032048 4e-06 -0.028422" quat="0.436273 0.55545 0.558752 0.434668" mass="1.75" diaginertia="0.00955766 0.00916707 0.00309615"/>
                  <joint name="RIGHT_ANKLE_X" pos="0 0 0" axis="1 0 0" range="-0.436332 0.436332" actuatorfrcrange="-1000 1000" damping="0.05"/>
                  <geom type="mesh" contype="0" conaffinity="0" group="1" density="0" mesh="foot"/>
                  <geom name="RIGHT" class="foot"/>
                </body>
              </body>
            </body>
          </body>
        </body>
      </body>
      <body name="SPINE_YAW_LINK" pos="0.08 0 0.00635">
        <inertial pos="-0.00853118 -2.697e-05 0.0379145" quat="0.000145501 0.744284 -0.000168113 0.667864" mass="0.91" diaginertia="0.00624244 0.00403003 0.00371344"/>
        <joint name="SPINE_Z" pos="0 0 0" axis="0 0 1" range="-1.0472 1.0472" actuatorfrcrange="-1000 1000" damping="0.05"/>
        <geom type="mesh" contype="0" conaffinity="0" group="1" density="0" mesh="spine_yaw"/>
        <body name="SPINE_ROLL_LINK" pos="0 0 0.08205">
          <inertial pos="-0.0190498 7e-08 0.0197924" quat="0.628592 0.32384 0.32384 0.628592" mass="0.44" diaginertia="0.000649978 0.000467109 0.000325562"/>
          <joint name="SPINE_X" pos="0 0 0" axis="1 0 0" range="-0.523599 0.523599" actuatorfrcrange="-1000 1000" damping="0.05"/>
          <geom type="mesh" contype="0" conaffinity="0" group="1" density="0" mesh="spine_roll"/>
          <body name="TORSO_LINK" pos="0 0 0.01">
            <inertial pos="-0.0361387 -2.81e-06 0.259086" quat="0.999765 0.000864511 0.0216369 0.00125896" mass="13.5" diaginertia="0.534796 0.50541 0.37911"/>
            <joint name="SPINE_Y" pos="0 0 0" axis="0 1 0" range="-1.0472 1.0472" actuatorfrcrange="-1000 1000" damping="0.05"/>
            <geom type="mesh" contype="0" conaffinity="0" group="1" density="0" mesh="torso_cycloidmounts"/>
            <body name="LEFT_SHOULDER_PITCH_LINK" pos="0.001 0.185 0.173" quat="0.853553 0.353553 -0.146447 -0.353553">
              <inertial pos="-0.00117 0.14001 -0.00621" quat="0.52476 0.468101 -0.460926 0.541346" mass="2.917" diaginertia="0.0115521 0.0108398 0.00485466"/>
              <joint name="LEFT_SHOULDER_Y" pos="0 0 0" axis="0 1 0" range="-3.14159 1.22173" actuatorfrcrange="-1000 1000" damping="0.05"/>
              <geom type="mesh" contype="0" conaffinity="0" group="1" density="0" mesh="LEFT_SHOULDER_PITCH_LINK"/>
              <body name="LEFT_SHOULDER_ROLL_LINK" pos="0 0.15676 -0.013" quat="0.92388 -0.382683 0 0">
                <inertial pos="0.01053 0.02124 -0.105269" quat="0.993677 0.0889004 0.0581547 0.0363529" mass="1.17068" diaginertia="0.0079679 0.00744654 0.00155216"/>
                <joint name="LEFT_SHOULDER_X" pos="0 0 0" axis="1 0 0" range="-0.261799 2.87979" actuatorfrcrange="-1000 1000" damping="0.05"/>
                <geom type="mesh" contype="0" conaffinity="0" group="1" density="0" mesh="LEFT_SHOULDER_ROLL_LINK"/>
                <body name="LEFT_SHOULDER_YAW_LINK" pos="0 0.035 0">
                  <inertial pos="0.00479 0.00062 -0.362414" quat="0.997214 -0.00851189 -0.0297516 0.0678708" mass="2.53059" diaginertia="0.0228533 0.0225942 0.00252544"/>
                  <joint name="LEFT_SHOULDER_Z" pos="0 0 0" axis="0 0 1" range="-1.91986 1.22173" actuatorfrcrange="-1000 1000" damping="0.05"/>
                  <geom type="mesh" contype="0" conaffinity="0" group="1" density="0" mesh="LEFT_SHOULDER_YAW_LINK"/>
                  <body name="LEFT_ELBOW_PITCH_LINK" pos="0.015 0 -0.4">
                    <inertial pos="-0.0109093 -0.0114719 -0.103887" quat="0.70708 0.0427709 -0.0172854 0.705627" mass="0.6007" diaginertia="0.00772841 0.00761665 0.000393237"/>
                    <joint name="LEFT_ELBOW_Y" pos="0 0 0" axis="0 1 0" range="-2.35619 0.174533" actuatorfrcrange="-1000 1000" damping="0.05"/>
                    <geom type="mesh" contype="0" conaffinity="0" group="1" density="0" mesh="LEFT_ELBOW_PITCH_LINK_413mm_LENGTH"/>
                  </body>
                </body>
              </body>
            </body>
            <body name="RIGHT_SHOULDER_PITCH_LINK" pos="0.001 -0.185 0.173" quat="0.853553 -0.353553 -0.146447 0.353553">
              <inertial pos="-0.00117 -0.14001 -0.00621" quat="0.52476 0.468101 -0.460926 0.541346" mass="2.917" diaginertia="0.0115521 0.0108398 0.00485466"/>
              <joint name="RIGHT_SHOULDER_Y" pos="0 0 0" axis="0 1 0" range="-3.14159 1.22173" actuatorfrcrange="-1000 1000" damping="0.05"/>
              <geom type="mesh" contype="0" conaffinity="0" group="1" density="0" mesh="RIGHT_SHOULDER_PITCH_LINK"/>
              <body name="RIGHT_SHOULDER_ROLL_LINK" pos="0 -0.15676 -0.013" quat="0.92388 0.382683 0 0">
                <inertial pos="-0.01053 -0.02124 -0.105269" quat="0.993677 -0.0889004 0.0581547 -0.0363529" mass="1.17068" diaginertia="0.0079679 0.00744654 0.00155216"/>
                <joint name="RIGHT_SHOULDER_X" pos="0 0 0" axis="1 0 0" range="-2.87979 0.261799" actuatorfrcrange="-1000 1000" damping="0.05"/>
                <geom type="mesh" contype="0" conaffinity="0" group="1" density="0" mesh="RIGHT_SHOULDER_ROLL_LINK"/>
                <body name="RIGHT_SHOULDER_YAW_LINK" pos="0 -0.035 0">
                  <inertial pos="0.00479 0.00062 -0.362414" quat="0.997214 -0.00851189 -0.0297516 0.0678708" mass="2.53059" diaginertia="0.0228533 0.0225942 0.00252544"/>
                  <joint name="RIGHT_SHOULDER_Z" pos="0 0 0" axis="0 0 1" range="-1.22173 1.91986" actuatorfrcrange="-1000 1000" damping="0.05"/>
                  <geom type="mesh" contype="0" conaffinity="0" group="1" density="0" mesh="RIGHT_SHOULDER_YAW_LINK"/>
                  <body name="RIGHT_ELBOW_PITCH_LINK" pos="0.015 0 -0.4">
                    <inertial pos="-0.0109093 -0.0114719 -0.103887" quat="0.70708 0.0427709 -0.0172854 0.705627" mass="0.6007" diaginertia="0.00772841 0.00761665 0.000393237"/>
                    <joint name="RIGHT_ELBOW_Y" pos="0 0 0" axis="0 1 0" range="-2.35619 0.174533" actuatorfrcrange="-1000 1000" damping="0.05"/>
                    <geom type="mesh" contype="0" conaffinity="0" group="1" density="0" mesh="RIGHT_ELBOW_PITCH_LINK_413mm_LENGTH"/>
                  </body>
                </body>
              </body>
            </body>
          </body>
        </body>
      </body>
    </body>
  </worldbody>
</mujoco>
