<?xml version = "1.0" ?>
<robot name="nadia" xmlns:xacro="http://www.ros.org/wiki/xacro">

<!-- revolute joints -->
<joint name="LEFT_HIP_Z" type="revolute">
    <origin rpy="0 0 0" xyz="0 0.115 -0.07185" />
    <axis xyz="0 0 -1" />
    <parent link="PELVIS_LINK" />
    <child link="LEFT_HIP_YAW_LINK" />
    <limit effort="1000" lower="-0.7854" upper="0.7854" velocity = "100" />
    <dynamics damping="0.05" friction="0.0"/>
</joint>

<joint name="RIGHT_HIP_Z" type="revolute">
    <origin rpy="0 0 0" xyz="0 -0.115 -0.07185" />
    <axis xyz="0 0 -1" />
    <parent link="PELVIS_LINK" />
    <child link="RIGHT_HIP_YAW_LINK" />
    <limit effort="1000" lower="-0.7854" upper="0.7854" velocity = "100" />
    <dynamics damping="0.05" friction="0.0"/>
</joint>

<joint name="LEFT_HIP_X" type="revolute">
    <origin rpy="0 0 0" xyz="0.035 0.015 -0.04975" />
    <axis xyz="1 0 0" />
    <parent link="LEFT_HIP_YAW_LINK" />
    <child link="LEFT_HIP_ROLL_LINK" />
    <limit effort="1000" lower="-0.5236" upper="1.0472" velocity = "100" />
    <dynamics damping="0.05" friction="0.0"/>
</joint>

<joint name="RIGHT_HIP_X" type="revolute">
    <origin rpy="0 0 0" xyz="0.035 -0.015 -0.04975" />
    <axis xyz="1 0 0" />
    <parent link="RIGHT_HIP_YAW_LINK" />
    <child link="RIGHT_HIP_ROLL_LINK" />
    <limit effort="1000" lower="-1.0472" upper="0.5236" velocity = "100" />
    <dynamics damping="0.05" friction="0.0"/>
</joint>

<joint name="LEFT_HIP_Y" type="revolute">
    <origin rpy="0 0 0" xyz="0 0 -0.079068" />
    <axis xyz="0 1 0" />
    <parent link="LEFT_HIP_ROLL_LINK" />
    <child link="LEFT_THIGH_LINK" />
    <limit effort="1000" lower="-1.57" upper="0.314" velocity = "100" />
    <dynamics damping="0.05" friction="0.0"/>
</joint>

<joint name="RIGHT_HIP_Y" type="revolute">
    <origin rpy="0 0 0" xyz="0 0 -0.079068" />
    <axis xyz="0 1 0" />
    <parent link="RIGHT_HIP_ROLL_LINK" />
    <child link="RIGHT_THIGH_LINK" />
    <limit effort="1000" lower="-1.57" upper="0.314" velocity = "100" />
    <dynamics damping="0.05" friction="0.0"/>
</joint>

<joint name="LEFT_KNEE_SHELL_UPPER_Y" type="revolute">
    <origin rpy="0 0 0" xyz="-0.02113091 0 -0.33468461" />
    <axis xyz="0 1 0" />
    <parent link="LEFT_THIGH_LINK" />
    <child link="LEFT_KNEE_SHELL_LINK" />
    <limit effort="1000" lower="0" upper="2.62" velocity = "100" />
    <dynamics damping="0.05" friction="0.0"/>
</joint>

<joint name="RIGHT_KNEE_SHELL_UPPER_Y" type="revolute">
    <origin rpy="0 0 0" xyz="-0.02113091 0 -0.33468461" />
    <axis xyz="0 1 0" />
    <parent link="RIGHT_THIGH_LINK" />
    <child link="RIGHT_KNEE_SHELL_LINK" />
    <limit effort="1000" lower="0" upper="2.62" velocity = "100" />
    <dynamics damping="0.05" friction="0.0"/>
</joint>

<joint name="LEFT_KNEE_LINKAGE_UPPER_Y" type="revolute">
    <origin rpy="0 0 0" xyz="0 0 -0.38" />
    <axis xyz="0 1 0" />
    <parent link="LEFT_THIGH_LINK" />
    <child link="LEFT_KNEE_LINKAGE_LINK" />
    <limit effort="1000" lower="0" upper="2.62" velocity = "100" />
    <dynamics damping="0.05" friction="0.0"/>
</joint>

<joint name="RIGHT_KNEE_LINKAGE_UPPER_Y" type="revolute">
    <origin rpy="0 0 0" xyz="0 0 -0.38" />
    <axis xyz="0 1 0" />
    <parent link="RIGHT_THIGH_LINK" />
    <child link="RIGHT_KNEE_LINKAGE_LINK" />
    <limit effort="1000" lower="0" upper="2.62" velocity = "100" />
    <dynamics damping="0.05" friction="0.0"/>
</joint>

<joint name="LEFT_KNEE_SHELL_LOWER_Y" type="revolute">
    <origin rpy="0 0 0" xyz="0.04231885 0 -0.10153381" />
    <axis xyz="0 1 0" />
    <parent link="LEFT_KNEE_SHELL_LINK" />
    <child link="LEFT_SHIN_LINK" />
    <limit effort="1000" lower="0" upper="2.62" velocity = "100" />
    <dynamics damping="0.05" friction="0.0"/>
</joint>

<joint name="RIGHT_KNEE_SHELL_LOWER_Y" type="revolute">
    <origin rpy="0 0 0" xyz="0.04231885 0 -0.10153381" />
    <axis xyz="0 1 0" />
    <parent link="RIGHT_KNEE_SHELL_LINK" />
    <child link="RIGHT_SHIN_LINK" />
    <limit effort="1000" lower="0" upper="2.62" velocity = "100" />
    <dynamics damping="0.05" friction="0.0"/>
</joint>

<!--joint name="LEFT_KNEE_LINKAGE_LOWER_Y" type="revolute">
    <origin rpy="0 0 0" xyz="-0.01711428 0 -0.0883578" />
    <axis xyz="0 1 0" />
    <parent link="LEFT_KNEE_LINKAGE_LINK" />
    <child link="LEFT_SHIN_LINK" />
    <limit effort="1000" lower="0" upper="2.62" velocity = "100" />
    <dynamics damping="0.05" friction="0.0"/>
</joint>

<joint name="RIGHT_KNEE_LINKAGE_LOWER_Y" type="revolute">
    <origin rpy="0 0 0" xyz="-0.01711428 0 -0.0883578" />
    <axis xyz="0 1 0" />
    <parent link="RIGHT_KNEE_LINKAGE_LINK" />
    <child link="RIGHT_SHIN_LINK" />
    <limit effort="1000" lower="0" upper="2.62" velocity = "100" />
    <dynamics damping="0.05" friction="0.0"/>
</joint-->

<joint name="LEFT_ANKLE_Y" type="revolute">
    <origin rpy="0 0 0" xyz="-0.00830222 0 -0.40213938" />
    <axis xyz="0 1 0" />
    <parent link="LEFT_SHIN_LINK" />
    <child link="LEFT_ANKLE_LINK" />
    <limit effort="1000" lower="-1.0472" upper="0.698132" velocity = "100" />
    <dynamics damping="0.05" friction="0.0"/>
</joint>

<joint name="RIGHT_ANKLE_Y" type="revolute">
    <origin rpy="0 0 0" xyz="-0.00830222 0 -0.40213938" />
    <axis xyz="0 1 0" />
    <parent link="RIGHT_SHIN_LINK" />
    <child link="RIGHT_ANKLE_LINK" />
    <limit effort="1000" lower="-1.0472" upper="0.698132" velocity = "100" />
    <dynamics damping="0.05" friction="0.0"/>
</joint>

<joint name="LEFT_ANKLE_X" type="revolute">
    <origin rpy="0 0 0" xyz="0 0 -0.01" />
    <axis xyz="1 0 0" />
    <parent link="LEFT_ANKLE_LINK" />
    <child link="LEFT_FOOT_LINK" />
    <limit effort="1000" lower="-0.436332" upper="0.436332" velocity = "100" />
    <dynamics damping="0.05" friction="0.0"/>
</joint>

<joint name="RIGHT_ANKLE_X" type="revolute">
    <origin rpy="0 0 0" xyz="0 0 -0.01" />
    <axis xyz="1 0 0" />
    <parent link="RIGHT_ANKLE_LINK" />
    <child link="RIGHT_FOOT_LINK" />
    <limit effort="1000" lower="-0.436332" upper="0.436332" velocity = "100" />
    <dynamics damping="0.05" friction="0.0"/>
</joint>

<joint name="SPINE_Z" type="revolute">
    <origin rpy="0 0 0" xyz="0.08 0 0.00635" />
    <axis xyz="0 0 1" />
    <parent link="PELVIS_LINK" />
    <child link="SPINE_YAW_LINK" />
    <limit effort="1000" lower="-1.0472" upper="1.0472" velocity = "100" />
    <dynamics damping="0.05" friction="0.0"/>
</joint>

<joint name="SPINE_X" type="revolute">
    <origin rpy="0 0 0" xyz="0 0 0.08205" />
    <axis xyz="1 0 0" />
    <parent link="SPINE_YAW_LINK" />
    <child link="SPINE_ROLL_LINK" />
    <limit effort="1000" lower="-0.523599" upper="0.523599" velocity = "100" />
    <dynamics damping="0.05" friction="0.0"/>
</joint>

<joint name="SPINE_Y" type="revolute">
    <origin rpy="0 0 0" xyz="0 0 0.01" />
    <axis xyz="0 1 0" />
    <parent link="SPINE_ROLL_LINK" />
    <child link="TORSO_LINK" />
    <limit effort="1000" lower="-1.0472" upper="1.0472" velocity = "100" />
    <dynamics damping="0.05" friction="0.0"/>
</joint>


<!-- links -->
<link name="PELVIS_LINK">
  <inertial>
    <mass value="19.0917"/>
    <origin rpy="0 0 0" xyz="0.02073086 2.023E-05 -0.0309812"/>
    <inertia ixx="0.0942" ixy="6.05E-06" ixz="0.000379" iyy="0.0416" iyz="3.37E-07" izz="0.112" />
  </inertial>
  <visual>
    <geometry>
      <mesh filename="package://nadia_V16_description/meshes/pelvis.obj"/>
    </geometry>
    <origin rpy="0.0 0.0 0.0" xyz="0.0 0.0 0.0"/>
  </visual>
</link>

<!-- pelvis_stim_imu -->
  <joint name="PELVIS_STIM_IMU_JOINT" type="fixed">
    <parent link="PELVIS_LINK"/>
    <child link="PELVIS_STIM_IMU_LINK"/>
    <origin xyz="-0.03133646 0.02237500 -0.07000000" rpy="0.0 3.141592 0.0"/>
  </joint>

  <link name="PELVIS_STIM_IMU_LINK">
    <inertial>
      <mass value="0.0" />
      <origin xyz="0 0 0" rpy="0 0 0" />
      <inertia ixx="0.0" ixy="0.0" ixz="0.0" iyy="0.0" iyz="0.0" izz="0.0" />
    </inertial>
  </link>

  <gazebo reference="PELVIS_STIM_IMU_LINK">
    <sensor name="pelvis_stim_imu" type="imu">
      <always_on>1</always_on>
      <update_rate>1000.0</update_rate>
      <imu>
        <noise>
          <type>gaussian</type>
          <rate>
            <mean>0.0</mean>
            <stddev>2e-4</stddev>
            <bias_mean>0.0000075</bias_mean>
            <bias_stddev>0.0000008</bias_stddev>
          </rate>
          <accel>
            <mean>0.0</mean>
            <stddev>1.7e-2</stddev>
            <bias_mean>0.1</bias_mean>
            <bias_stddev>0.001</bias_stddev>
          </accel>
        </noise>
      </imu>
    </sensor>
  </gazebo>
 <!-- end pelvis stim imu -->

<link name="LEFT_HIP_YAW_LINK">
  <inertial>
    <mass value="1.814"/>
    <origin rpy="0 0 0" xyz="-0.00629727 0.00606893 -0.03971844"/>
    <inertia ixx="0.004741914" ixy="0.000527" ixz="-0.000307" iyy="0.00414" iyz="1.36E-05" izz="0.00569" />
  </inertial>
  <visual>
    <geometry>
      <mesh filename="package://nadia_V16_description/meshes/left_hip_yaw.obj"/>
    </geometry>
    <origin rpy="0.0 0.0 0.0" xyz="0.0 0.0 0.0"/>
  </visual>
</link>

<link name="RIGHT_HIP_YAW_LINK">
  <inertial>
    <mass value="1.814"/>
    <origin rpy="0 0 0" xyz="-0.00629727 -0.00606893 -0.03971844"/>
    <inertia ixx="0.004741914" ixy="-0.000527" ixz="-0.000307" iyy="0.00414" iyz="-1.36E-05" izz="0.00569" />
  </inertial>
  <visual>
    <geometry>
      <mesh filename="package://nadia_V16_description/meshes/right_hip_yaw.obj"/>
    </geometry>
    <origin rpy="0.0 0.0 0.0" xyz="0.0 0.0 0.0"/>
  </visual>
</link>

<link name="LEFT_HIP_ROLL_LINK">
  <inertial>
    <mass value="0.762"/>
    <origin rpy="0 0 0" xyz="-0.01327037 0.00316985 -0.05399997"/>
    <inertia ixx="0.001028994" ixy="-9.31E-06" ixz="0.000352" iyy="0.00138" iyz="3.22E-05" izz="0.000663" />
  </inertial>
  <visual>
    <geometry>
      <mesh filename="package://nadia_V16_description/meshes/left_hip_roll.obj"/>
    </geometry>
    <origin rpy="0.0 0.0 0.0" xyz="0.0 0.0 0.0"/>
  </visual>
</link>

<link name="RIGHT_HIP_ROLL_LINK">
  <inertial>
    <mass value="0.762"/>
    <origin rpy="0 0 0" xyz="-0.01327037 -0.00316985 -0.05399997"/>
    <inertia ixx="0.001028994" ixy="9.31E-06" ixz="0.000352" iyy="0.00138" iyz="-3.22E-05" izz="0.000663" />
  </inertial>
  <visual>
    <geometry>
      <mesh filename="package://nadia_V16_description/meshes/right_hip_roll.obj"/>
    </geometry>
    <origin rpy="0.0 0.0 0.0" xyz="0.0 0.0 0.0"/>
  </visual>
</link>

<link name="LEFT_THIGH_LINK">
  <inertial>
    <mass value="10.953"/>
    <origin rpy="0 0 0" xyz="-0.00093749 0.01134511 -0.17863144"/>
    <inertia ixx="0.1622268263" ixy="-0.000749" ixz="0.0156" iyy="0.174" iyz="0.00213" izz="0.0528" />
  </inertial>
  <visual>
    <geometry>
      <mesh filename="package://nadia_V16_description/meshes/left_thigh.obj"/>
    </geometry>
    <origin rpy="0.0 0.0 0.0" xyz="0.0 0.0 0.0"/>
  </visual>
</link>

<!-- left thigh imu -->
  <joint name="LEFT_THIGH_IMU_JOINT" type="fixed">
    <parent link="LEFT_THIGH_LINK"/>
    <child link="LEFT_THIGH_IMU_LINK"/>
    <origin xyz="0.05793744 0.01666131 -0.09511697" rpy="2.025  0.000 -1.571"/>  
  </joint>

  <link name="LEFT_THIGH_IMU_LINK">
    <inertial>
      <mass value="0.0" />
      <origin xyz="0 0 0" rpy="0 0 0" />
      <inertia ixx="0.0" ixy="0.0" ixz="0.0" iyy="0.0" iyz="0.0" izz="0.0" />
    </inertial>
  </link>

  <gazebo reference="LEFT_THIGH_IMU_LINK">
    <sensor name="left_thigh_imu" type="imu">
      <always_on>1</always_on>
      <update_rate>1000.0</update_rate>
      <imu>
        <noise>
          <type>gaussian</type>
          <rate>
            <mean>0.0</mean>
            <stddev>2e-4</stddev>
            <bias_mean>0.0000075</bias_mean>
            <bias_stddev>0.0000008</bias_stddev>
          </rate>
          <accel>
            <mean>0.0</mean>
            <stddev>1.7e-2</stddev>
            <bias_mean>0.1</bias_mean>
            <bias_stddev>0.001</bias_stddev>
          </accel>
        </noise>
      </imu>
    </sensor>
  </gazebo>
<!-- end left thigh imu -->

<link name="RIGHT_THIGH_LINK">
  <inertial>
    <mass value="10.953"/>
    <origin rpy="0 0 0" xyz="-0.00093749 -0.01134511 -0.17863144"/>
    <inertia ixx="0.1622268263" ixy="0.000749" ixz="0.0156" iyy="0.174" iyz="-0.00213" izz="0.0528" />
  </inertial>
  <visual>
    <geometry>
      <mesh filename="package://nadia_V16_description/meshes/right_thigh.obj"/>
    </geometry>
    <origin rpy="0.0 0.0 0.0" xyz="0.0 0.0 0.0"/>
  </visual>
</link>

<!-- right thigh imu -->
  <joint name="RIGHT_THIGH_IMU_JOINT" type="fixed">
    <parent link="RIGHT_THIGH_LINK"/>
    <child link="RIGHT_THIGH_IMU_LINK"/>
    <origin xyz="0.05793670 0.01066129 -0.09511742" rpy="2.025  0.000 -1.571"/>  
  </joint>

  <link name="RIGHT_THIGH_IMU_LINK">
    <inertial>
      <mass value="0.0" />
      <origin xyz="0 0 0" rpy="0 0 0" />
      <inertia ixx="0.0" ixy="0.0" ixz="0.0" iyy="0.0" iyz="0.0" izz="0.0" />
    </inertial>
  </link>

  <gazebo reference="RIGHT_THIGH_IMU_LINK">
    <sensor name="right_thigh_imu" type="imu">
      <always_on>1</always_on>
      <update_rate>1000.0</update_rate>
      <imu>
        <noise>
          <type>gaussian</type>
          <rate>
            <mean>0.0</mean>
            <stddev>2e-4</stddev>
            <bias_mean>0.0000075</bias_mean>
            <bias_stddev>0.0000008</bias_stddev>
          </rate>
          <accel>
            <mean>0.0</mean>
            <stddev>1.7e-2</stddev>
            <bias_mean>0.1</bias_mean>
            <bias_stddev>0.001</bias_stddev>
          </accel>
        </noise>
      </imu>
    </sensor>
  </gazebo>
<!-- end right thigh imu -->

<link name="LEFT_KNEE_LINKAGE_LINK">
  <inertial>
    <mass value="0.936"/>
    <origin rpy="0 0 0" xyz="0.00901763 0.00753613 -0.04368231"/>
    <inertia ixx="0.002617337" ixy="3.06E-07" ixz="0.000313" iyy="0.00159" iyz="1.51E-06" izz="0.00128" />
  </inertial>
  <visual>
    <geometry>
      <mesh filename="package://nadia_V16_description/meshes/left_knee_linkage.obj"/>
    </geometry>
    <origin rpy="0.0 0.0 0.0" xyz="0.0 0.0 0.0"/>
  </visual>
</link>

<link name="RIGHT_KNEE_LINKAGE_LINK">
  <inertial>
    <mass value="0.936"/>
    <origin rpy="0 0 0" xyz="0.00901763 -0.00753613 -0.04368231"/>
    <inertia ixx="0.002617337" ixy="-3.06E-07" ixz="0.000313" iyy="0.00159" iyz="-1.51E-06" izz="0.00128" />
  </inertial>
  <visual>
    <geometry>
      <mesh filename="package://nadia_V16_description/meshes/right_knee_linkage.obj"/>
    </geometry>
    <origin rpy="0.0 0.0 0.0" xyz="0.0 0.0 0.0"/>
  </visual>
</link>

<link name="LEFT_KNEE_SHELL_LINK">
  <inertial>
    <mass value="1.101"/>
    <origin rpy="0 0 0" xyz="0.02489954 0.00826196 -0.05330217"/>
    <inertia ixx="0.00642" ixy="-3.64E-05" ixz="1.43E-05" iyy="0.00456" iyz="-6.54E-05" izz="0.00566" />
  </inertial>
  <visual>
    <geometry>
      <mesh filename="package://nadia_V16_description/meshes/left_knee_shell.obj"/>
    </geometry>
    <origin rpy="0.0 0.0 0.0" xyz="0.0 0.0 0.0"/>
  </visual>
</link>

<link name="RIGHT_KNEE_SHELL_LINK">
  <inertial>
    <mass value="1.101"/>
    <origin rpy="0 0 0" xyz="0.02489954 -0.00826196 -0.05330217"/>
    <inertia ixx="0.00642" ixy="3.64E-05" ixz="1.43E-05" iyy="0.00456" iyz="6.54E-05" izz="0.00566" />
  </inertial>
  <visual>
    <geometry>
      <mesh filename="package://nadia_V16_description/meshes/right_knee_shell.obj"/>
    </geometry>
    <origin rpy="0.0 0.0 0.0" xyz="0.0 0.0 0.0"/>
  </visual>
</link>

<link name="LEFT_SHIN_LINK">
  <inertial>
    <mass value="5.42"/>
    <origin rpy="0 0 0" xyz="-0.01841492 0.00228086 -0.22054239"/>
    <inertia ixx="0.064437783" ixy="-0.000214" ixz="-0.00538" iyy="0.0583" iyz="-0.000962" izz="0.0136" />
  </inertial>
  <visual>
    <geometry>
      <mesh filename="package://nadia_V16_description/meshes/left_shin.obj"/>
    </geometry>
    <origin rpy="0.0 0.0 0.0" xyz="0.0 0.0 0.0"/>
  </visual>
</link>


<!-- left shin imu -->
  <joint name="LEFT_SHIN_IMU_JOINT" type="fixed">
    <parent link="LEFT_SHIN_LINK"/>
    <child link="LEFT_SHIN_IMU_LINK"/>
    <origin xyz="-0.03216129 -0.07159184 -0.1864738" rpy="-1.570796 0.0 0.0"/>  
  </joint>

  <link name="LEFT_SHIN_IMU_LINK">
    <inertial>
      <mass value="0.0" />
      <origin xyz="0 0 0" rpy="0 0 0" />
      <inertia ixx="0.0" ixy="0.0" ixz="0.0" iyy="0.0" iyz="0.0" izz="0.0" />
    </inertial>
  </link>

  <gazebo reference="LEFT_SHIN_IMU_LINK">
    <sensor name="left_shin_imu" type="imu">
      <always_on>1</always_on>
      <update_rate>1000.0</update_rate>
      <imu>
        <noise>
          <type>gaussian</type>
          <rate>
            <mean>0.0</mean>
            <stddev>2e-4</stddev>
            <bias_mean>0.0000075</bias_mean>
            <bias_stddev>0.0000008</bias_stddev>
          </rate>
          <accel>
            <mean>0.0</mean>
            <stddev>1.7e-2</stddev>
            <bias_mean>0.1</bias_mean>
            <bias_stddev>0.001</bias_stddev>
          </accel>
        </noise>
      </imu>
    </sensor>
  </gazebo>
<!-- end left shin imu -->

<link name="RIGHT_SHIN_LINK">
  <inertial>
    <mass value="5.42"/>
    <origin rpy="0 0 0" xyz="-0.01837047 -0.00241134 -0.21991278"/>
    <inertia ixx="0.064443143" ixy="0.000202" ixz="-0.00539" iyy="0.0583" iyz="0.000906" izz="0.0136" />
  </inertial>
  <visual>
    <geometry>
      <mesh filename="package://nadia_V16_description/meshes/right_shin.obj"/>
    </geometry>
    <origin rpy="0.0 0.0 0.0" xyz="0.0 0.0 0.0"/>
  </visual>
</link>

<!-- right shin imu -->
  <joint name="RIGHT_SHIN_IMU_JOINT" type="fixed">
    <parent link="RIGHT_SHIN_LINK"/>
    <child link="RIGHT_SHIN_IMU_LINK"/>
    <origin xyz="-0.002838710 0.07159142 -0.1864738" rpy="-1.570796 0.0 3.141592"/>  
  </joint>

  <link name="RIGHT_SHIN_IMU_LINK">
    <inertial>
      <mass value="0.0" />
      <origin xyz="0 0 0" rpy="0 0 0" />
      <inertia ixx="0.0" ixy="0.0" ixz="0.0" iyy="0.0" iyz="0.0" izz="0.0" />
    </inertial>
  </link>

  <gazebo reference="RIGHT_SHIN_IMU_LINK">
    <sensor name="right_shin_imu" type="imu">
      <always_on>1</always_on>
      <update_rate>1000.0</update_rate>
      <imu>
        <noise>
          <type>gaussian</type>
          <rate>
            <mean>0.0</mean>
            <stddev>2e-4</stddev>
            <bias_mean>0.0000075</bias_mean>
            <bias_stddev>0.0000008</bias_stddev>
          </rate>
          <accel>
            <mean>0.0</mean>
            <stddev>1.7e-2</stddev>
            <bias_mean>0.1</bias_mean>
            <bias_stddev>0.001</bias_stddev>
          </accel>
        </noise>
      </imu>
    </sensor>
  </gazebo>
<!-- end right shin imu -->

<link name="LEFT_ANKLE_LINK">
  <inertial>
    <mass value="0.56"/>
    <origin rpy="0 0 0" xyz="-0.00072338 -6.619E-05 -0.00399965"/>
    <inertia ixx="0.000459" ixy="2.65E-08" ixz="-2.43E-06" iyy="0.000336" iyz="1.48E-07" izz="0.000645" />
  </inertial>
  <visual>
    <geometry>
      <mesh filename="package://nadia_V16_description/meshes/ankle.obj"/>
    </geometry>
    <origin rpy="0.0 0.0 0.0" xyz="0.0 0.0 0.0"/>
  </visual>
</link>

<link name="RIGHT_ANKLE_LINK">
  <inertial>
    <mass value="0.56"/>
    <origin rpy="0 0 0" xyz="-0.00072338 6.619E-05 -0.00399965"/>
    <inertia ixx="0.000459" ixy="-2.65E-08" ixz="-2.43E-06" iyy="0.000336" iyz="-1.48E-07" izz="0.000645" />
  </inertial>
  <visual>
    <geometry>
      <mesh filename="package://nadia_V16_description/meshes/ankle.obj"/>
    </geometry>
    <origin rpy="0.0 0.0 0.0" xyz="0.0 0.0 0.0"/>
  </visual>
</link>

<link name="LEFT_FOOT_LINK">
  <inertial>
    <mass value="1.75"/>
    <origin rpy="0 0 0" xyz="0.03075449 0.00007807 -0.04382467"/>
    <inertia ixx="0.00345011" ixy="-0.0000073" ixz="0.0014225" iyy="0.00955764" iyz="-2.269e-7" izz="0.00881313" />
  </inertial>
  <visual>
    <geometry>
      <mesh filename="package://nadia_V16_description/meshes/foot.obj"/>
    </geometry>
    <origin rpy="0.0 0.0 0.0" xyz="0.0 0.0 0.0"/>
  </visual>
</link>

<link name="RIGHT_FOOT_LINK">
  <inertial>
    <mass value="1.75"/>
    <origin rpy="0 0 0" xyz="0.032048 4e-06 -0.028422"/>
    <inertia ixx="0.00345011" ixy="-0.0000073" ixz="0.0014225" iyy="0.00955764" iyz="-2.269e-7" izz="0.00881313" />
  </inertial>
  <visual>
    <geometry>
      <mesh filename="package://nadia_V16_description/meshes/foot.obj"/>
    </geometry>
    <origin rpy="0.0 0.0 0.0" xyz="0.0 0.0 0.0"/>
  </visual>
</link>

<link name="SPINE_YAW_LINK">
  <inertial>
    <mass value="0.91"/>
    <origin rpy="0 0 0" xyz="-0.00853118 -2.697E-05 0.03791445"/>
    <inertia ixx="0.00374289408" ixy="1.25497934E-07" ixz="0.000271325072" iyy="0.00403002777" iyz="-1.38015692E-07" izz="0.0062129847" />
  </inertial>
  <visual>
    <geometry>
      <mesh filename="package://nadia_V16_description/meshes/spine_yaw.obj"/>
    </geometry>
    <origin rpy="0.0 0.0 0.0" xyz="0.0 0.0 0.0"/>
  </visual>
</link>

<link name="SPINE_ROLL_LINK">
  <inertial>
    <mass value="0.44"/>
    <origin rpy="0 0 0" xyz="-0.01904983 7E-08 0.01979244"/>
    <inertia ixx="0.000373262301" ixy="-1.51441878E-10" ixz="-6.69067307E-05" iyy="0.000649978475" iyz="-1.27858402E-10" izz="0.000419408851" />
  </inertial>
  <visual>
    <geometry>
      <mesh filename="package://nadia_V16_description/meshes/spine_roll.obj"/>
    </geometry>
    <origin rpy="0.0 0.0 0.0" xyz="0.0 0.0 0.0"/>
  </visual>
</link>

<link name="TORSO_LINK">
  <inertial>
    <mass value="13.5"/>
    <origin rpy="0 0 0" xyz="-0.03613868 -2.81E-06 0.25908586"/>
    <inertia ixx="0.534504681" ixy="8.41519717E-05" ixz="-0.00672956305" iyy="0.505409852" iyz="0.000207996773" izz="0.379402013" />
  </inertial>
  <visual>
    <geometry>
      <mesh filename="package://nadia_V16_description/meshes/torso_cycloidmounts.obj"/>
    </geometry>
    <origin rpy="0.0 0.0 0.0" xyz="0.0 0.0 0.0"/>
  </visual>
</link>

<!-- torso imu -->
  <joint name="TORSO_IMU_JOINT" type="fixed">
    <parent link="TORSO_LINK"/>
    <child link="TORSO_IMU_LINK"/>
    <origin xyz="0.04529 -0.02427 0.33757" rpy="3.141592 0 0"/>  
  </joint>

  <link name="TORSO_IMU_LINK">
    <inertial>
      <mass value="0.0" />
      <origin xyz="0 0 0" rpy="0 0 0" />
      <inertia ixx="0.0" ixy="0.0" ixz="0.0" iyy="0.0" iyz="0.0" izz="0.0" />
    </inertial>
  </link>

  <gazebo reference="TORSO_IMU_LINK">
    <sensor name="TORSO_imu" type="imu">
      <always_on>1</always_on>
      <update_rate>1000.0</update_rate>
      <imu>
        <noise>
          <type>gaussian</type>
          <rate>
            <mean>0.0</mean>
            <stddev>2e-4</stddev>
            <bias_mean>0.0000075</bias_mean>
            <bias_stddev>0.0000008</bias_stddev>
          </rate>
          <accel>
            <mean>0.0</mean>
            <stddev>1.7e-2</stddev>
            <bias_mean>0.1</bias_mean>
            <bias_stddev>0.001</bias_stddev>
          </accel>
        </noise>
      </imu>
    </sensor>
  </gazebo>
<!-- end torso imu -->
</robot>
