<?xml version = "1.0" ?>
<robot name="nadia" xmlns:xacro="http://www.ros.org/wiki/xacro">
<joint name="LEFT_SHOULDER_Y" type="revolute">
    <origin rpy="0.78539816 0.0  -1.57079632679" xyz="0.13144909 0 0.11023589" />
    <axis xyz="0.0 1.0 0.0" />
    <parent link="TORSO_LINK" />
    <child link="LEFT_SHOULDER_PITCH_LINK" />
    <limit effort="1000" lower="-3.141592" upper="1.22173" velocity = "100" />
    <dynamics damping="0.05" friction="0.0"/>
</joint>
<joint name="LEFT_SHOULDER_X" type="revolute">
    <origin rpy="-0.785398163 0.0 0.0" xyz="0.0 0.15676000 -0.01300000" />
    <axis xyz="1 0 0" />
    <parent link="LEFT_SHOULDER_PITCH_LINK" />
    <child link="LEFT_SHOULDER_ROLL_LINK" />
    <limit effort="1000" lower="-0.261799" upper="2.87979" velocity = "100" />
    <dynamics damping="0.05" friction="0.0"/>
</joint>
<joint name="LEFT_SHOULDER_Z" type="revolute">
    <origin rpy="0.0 0.0 0.0" xyz="0.0 0.035 0.0" />
    <axis xyz="0.0 0.0 1.0" />
    <parent link="LEFT_SHOULDER_ROLL_LINK" />
    <child link="LEFT_SHOULDER_YAW_LINK" />
    <limit effort="1000" lower="-1.91986" upper="1.22173" velocity = "100" />
    <dynamics damping="0.05" friction="0.0"/>
</joint>
<joint name="LEFT_ELBOW_Y" type="revolute">
    <origin rpy="0.0 0.0 0.0" xyz="0.015 0.0 -0.4" />
    <axis xyz="0.0 1.0 0.0" />
    <parent link="LEFT_SHOULDER_YAW_LINK" />
    <child link="LEFT_ELBOW_PITCH_LINK" />
    <limit effort="1000" lower="-2.35619" upper="0.174532925" velocity = "100" />
    <dynamics damping="0.05" friction="0.0"/>
</joint>
<link name="TORSO_LINK">
  <inertial>
    <mass value="13.75252575"/>
    <origin rpy="0 0 0" xyz="0.0488461900 0.0000587900 0.0707804300"/>
    <inertia ixx="0.1666638600" ixy="-0.0000199200" ixz="-0.0578881300" iyy="0.2305939100" iyz="-0.0000724700" izz="0.2604723800" />
	
  </inertial>
  <visual>
    <geometry>
      <mesh filename="package://nadia_V17_description/meshes/cycloidal_arm/TORSO_LINK.obj"/>
    </geometry>
    <origin rpy="0.0 0.0 0.0" xyz="0.0 0.0 0.0"/>
  </visual>
</link>
<link name="LEFT_SHOULDER_PITCH_LINK">
  <inertial>
    <mass value="2.917"/>
    <origin rpy="0 0 0" xyz="-0.00117 0.1400097 -0.00621"/>
    <inertia ixx="0.0108367" ixy="1.356e-4" ixz="-2.666e-5" iyy="0.00498324" iyz="0.00090758" izz="0.01142661" />
  </inertial>
  <visual>
    <geometry>
      <mesh filename="package://nadia_V17_description/meshes/cycloidal_arm/LEFT_SHOULDER_PITCH_LINK.obj"/>
    </geometry>
    <origin rpy="0.0 0.0 0.0" xyz="0.0 0.0 0.0"/>
  </visual>
</link>


<link name="LEFT_SHOULDER_ROLL_LINK">
  <inertial>
    <mass value="1.17068"/>
    <origin rpy="0 0 0" xyz="0.01053 0.02124 -0.1052690"/>
    <inertia ixx="0.00787035" ixy="1.667e-4" ixz="-0.00075945" iyy="0.00727481" iyz="0.000988837" izz="0.00182144" />
  </inertial>
  <visual>
    <geometry>
      <mesh filename="package://nadia_V17_description/meshes/cycloidal_arm/LEFT_SHOULDER_ROLL_LINK.obj"/>
    </geometry>
    <origin rpy="0.0 0.0 0.0" xyz="0.0 0.0 0.0"/>
  </visual>
</link>
<link name="LEFT_SHOULDER_YAW_LINK">
  <inertial>
    <mass value="2.53059"/>
    <origin rpy="0 0 0" xyz="0.00479 0.00062 -0.3624141"/>
    <inertia ixx="0.02277422" ixy="5.053e-5" ixz="0.0012266" iyy="0.0225956" iyz="-2.571e-4" izz="0.00260312" />
  </inertial>
  <visual>
    <geometry>
      <mesh filename="package://nadia_V17_description/meshes/cycloidal_arm/LEFT_SHOULDER_YAW_LINK.obj"/>
    </geometry>
    <origin rpy="0.0 0.0 0.0" xyz="0.0 0.0 0.0"/>
  </visual>
</link>
<link name="LEFT_ELBOW_PITCH_LINK">
  <inertial>
    <mass value="0.6007"/>
    <origin rpy="0 0 0" xyz="-0.01090935 -0.01147189 -0.10388715"/>
    <inertia ixx="0.00760733" ixy="2.242e-5" ixz="-2.583e-4" iyy="0.00767556" iyz="0.00061995" izz="4.554e-4" />
  </inertial>
  <visual>
    <geometry>
      <mesh filename="package://nadia_V17_description/meshes/cycloidal_arm/LEFT_ELBOW_PITCH_LINK_413mm_LENGTH.obj"/>
    </geometry>
    <origin rpy="0.0 0.0 0.0" xyz="0.0 0.0 0.0"/>
  </visual>
</link>




<!-- Preview robot -->
<joint name="PREVIEW_LEFT_SHOULDER_Y" type="revolute">
    <origin rpy="0.78539816 0.0  -1.57079632679" xyz="0.13144909 0 0.11023589" />
    <axis xyz="0.0 1.0 0.0" />
    <parent link="TORSO_LINK" />
    <child link="PREVIEW_LEFT_SHOULDER_PITCH_LINK" />
    <limit effort="1000" lower="-3.141592" upper="1.22173" velocity = "100" />
    <dynamics damping="0.05" friction="0.0"/>
</joint>
<joint name="PREVIEW_LEFT_SHOULDER_X" type="revolute">
    <origin rpy="-0.785398163 0.0 0.0" xyz="0.0 0.15676000 -0.01300000" />
    <axis xyz="1 0 0" />
    <parent link="PREVIEW_LEFT_SHOULDER_PITCH_LINK" />
    <child link="PREVIEW_LEFT_SHOULDER_ROLL_LINK" />
    <limit effort="1000" lower="-0.261799" upper="2.87979" velocity = "100" />
    <dynamics damping="0.05" friction="0.0"/>
</joint>
<joint name="PREVIEW_LEFT_SHOULDER_Z" type="revolute">
    <origin rpy="0.0 0.0 0.0" xyz="0.0 0.035 0.0" />
    <axis xyz="0.0 0.0 1.0" />
    <parent link="PREVIEW_LEFT_SHOULDER_ROLL_LINK" />
    <child link="PREVIEW_LEFT_SHOULDER_YAW_LINK" />
    <limit effort="1000" lower="-1.91986" upper="1.22173" velocity = "100" />
    <dynamics damping="0.05" friction="0.0"/>
</joint>
<joint name="PREVIEW_LEFT_ELBOW_Y" type="revolute">
    <origin rpy="0.0 0.0 0.0" xyz="0.015 0.0 -0.4" />
    <axis xyz="0.0 1.0 0.0" />
    <parent link="PREVIEW_LEFT_SHOULDER_YAW_LINK" />
    <child link="PREVIEW_LEFT_ELBOW_PITCH_LINK" />
    <limit effort="1000" lower="-2.35619" upper="0.174532925" velocity = "100" />
    <dynamics damping="0.05" friction="0.0"/>
</joint>

<link name="PREVIEW_LEFT_SHOULDER_PITCH_LINK">
  <inertial>
    <mass value="2.917"/>
    <origin rpy="0 0 0" xyz="-0.00117 0.11905 -0.00621"/>
    <inertia ixx="0.0108367" ixy="1.356e-4" ixz="-2.666e-5" iyy="0.00498324" iyz="0.00090758" izz="0.01142661" />
  </inertial>
  <visual>
    <geometry>
      <mesh filename="package://nadia_V17_description/meshes/cycloidal_arm/LEFT_SHOULDER_PITCH_LINK.obj"/>
    </geometry>
    <origin rpy="0.0 0.0 0.0" xyz="0.0 0.0 0.0"/>
  </visual>
</link>
<link name="PREVIEW_LEFT_SHOULDER_ROLL_LINK">
 <inertial>
    <mass value="1.17068"/>
    <origin rpy="0 0 0" xyz="0.01053 0.02124 -0.07298"/>
    <inertia ixx="0.00787035" ixy="1.667e-4" ixz="-0.00075945" iyy="0.00727481" iyz="0.000988837" izz="0.00182144" />    
  </inertial>
  <visual>
    <geometry>
      <mesh filename="package://nadia_V17_description/meshes/cycloidal_arm/LEFT_SHOULDER_ROLL_LINK.obj"/>
    </geometry>
    <origin rpy="0.0 0.0 0.0" xyz="0.0 0.0 0.0"/>
  </visual>
</link>
<link name="PREVIEW_LEFT_SHOULDER_YAW_LINK">
  <inertial>
    <mass value="2.53059"/>
    <origin rpy="0 0 0" xyz="0.00479 0.00062 -0.30231"/>
    <inertia ixx="0.02277422" ixy="5.053e-5" ixz="0.0012266" iyy="0.0225956" iyz="-2.571e-4" izz="0.00260312" />
  </inertial>
  <visual>
    <geometry>
      <mesh filename="package://nadia_V17_description/meshes/cycloidal_arm/LEFT_SHOULDER_YAW_LINK.obj"/>
    </geometry>
    <origin rpy="0.0 0.0 0.0" xyz="0.0 0.0 0.0"/>
  </visual>
</link>
<link name="PREVIEW_LEFT_ELBOW_PITCH_LINK">
   <inertial>
    <mass value="0.6007"/>
    <origin rpy="0 0 0" xyz="-0.01090935 -0.01147189 -0.10656216"/>
    <inertia ixx="0.00760733" ixy="2.242e-5" ixz="-2.583e-4" iyy="0.00767556" iyz="0.00061995" izz="4.554e-4" />
  </inertial>
  <visual>
    <geometry>
      <mesh filename="package://nadia_V17_description/meshes/cycloidal_arm/LEFT_ELBOW_PITCH_LINK_413mm_LENGTH.obj"/>
    </geometry>
    <origin rpy="0.0 0.0 0.0" xyz="0.0 0.0 0.0"/>
  </visual>
</link>
<!-- IMU Information --> 
<link name="shoulderPitchIMU_Frame">
    <inertial>
      <mass value="1e-07"/>
      <origin rpy="0 0 0" xyz="0 0 0"/>
      <inertia ixx="3.3333333333333322e-22" ixy="0.0" ixz="0.0" iyy="3.3333333333333322e-22" iyz="0.0" izz="4.999999999999999e-22"/>
    </inertial>
</link>
<joint name="shoulderPitchIMU_Offset" type="fixed">
	<origin rpy="-1.570796 1.570796 0" xyz="0.0174 0.06944 -0.03025"/>
	<axis xyz="0 0 1"/>
	<parent link="LEFT_SHOULDER_PITCH_LINK"/>
	<child link="shoulderPitchIMU_Frame"/>
</joint>
<gazebo reference="shoulderPitchIMU_Offset">
    <implicitSpringDamper>1</implicitSpringDamper>
</gazebo>
<gazebo>
<plugin filename="libgazebo_ros_imu.so" name="imu_plugin_ros">
  <alwaysOn>true</alwaysOn>
  <bodyName>shoulderPitchIMU_Frame</bodyName>
  <topicName>shoulderPitchIMU/imu</topicName>
  <serviceName>shoulderPitchIMU/imu_service</serviceName>
  <gaussianNoise>0.0</gaussianNoise>
  <updateRate>1000.0</updateRate>
</plugin>
</gazebo>
<gazebo reference="shoulderPitchIMU_Frame">

<!-- Note: in CAD this is the shoulder roll IMU since it's connected to the shoulder roll ethersnacks board -->
<sensor name="shoulderPitchIMU" type="imu">
  <imuTransform>0.0174 0.06944 -0.03025 -1.570796 1.570796 0</imuTransform>
  <always_on>true</always_on>
  <pose>0 0 0 0 0 0 </pose>
  <node name="/sensors/shoulderPitchIMU"/>
  <api name="IMU_ICM42688P_Sensor::IMU_ICM42688P_Sensor"/>
  <port name="/dev/ttyS4"/>
  <imu>
	<noise>
	  <type>gaussian</type>
	  <rate>
		<mean>0</mean>
		<stddev>0.0002</stddev>
		<bias_mean>7.5e-06</bias_mean>
		<bias_stddev>8e-07</bias_stddev>
	  </rate>
	  <accel>
		<mean>0</mean>
		<stddev>0.017</stddev>
		<bias_mean>0.1</bias_mean>
		<bias_stddev>0.001</bias_stddev>
	  </accel>
	</noise>
  </imu>
</sensor>
</gazebo>

<!-- ShoulderYaw IMU -->
<!-- Note: in CAD this is the left bicep IMU -->
<link name="ShoulderYawIMU_Frame">
    <!-- Virtual Link  -->
    <inertial>
      <mass value="1e-07"/>
      <origin rpy="0 0 0" xyz="0 0 0"/>
      <inertia ixx="3.3333333333333322e-22" ixy="0.0" ixz="0.0" iyy="3.3333333333333322e-22" iyz="0.0" izz="4.999999999999999e-22"/>
    </inertial>
 </link>
<joint name="ShoulderYawIMU_Offset" type="fixed">
	<origin rpy="-1.570796 3.1415926 -0.314159" xyz="-0.00763459 -0.0123324 -0.318"/>
	<axis xyz="0 0 1"/>
	<parent link="LEFT_SHOULDER_YAW_LINK"/> 
	<child link="ShoulderYawIMU_Frame"/>
</joint>
<gazebo reference="ShoulderYawIMU_Offset">
	<implicitSpringDamper>1</implicitSpringDamper>
</gazebo>
<gazebo>
<plugin filename="libgazebo_ros_imu.so" name="imu_plugin_ros">
  <alwaysOn>true</alwaysOn>
  <bodyName>ShoulderYawIMU_Frame</bodyName>
  <topicName>ShoulderYawIMU/imu</topicName>
  <serviceName>ShoulderYawIMU/imu_service</serviceName>
  <gaussianNoise>0.0</gaussianNoise>
  <updateRate>1000.0</updateRate>
</plugin>
</gazebo>
<gazebo reference="ShoulderYawIMU_Frame">
<sensor name="ShoulderYawIMU" type="imu">
  <imuTransform>-0.00763459 -0.0123324 -0.318 -1.570796 3.1415926 -0.314159</imuTransform>
  <always_on>true</always_on>
  <pose>0 0 0 0 0 0 </pose>
  <node name="/sensors/ShoulderYawIMU"/>
  <api name="IMU_ICM42688P_Sensor::IMU_ICM42688P_Sensor"/>
  <port name="/dev/ttyS4"/>
  <imu>
	<noise>
	  <type>gaussian</type>
	  <rate>
		<mean>0</mean>
		<stddev>0.0002</stddev>
		<bias_mean>7.5e-06</bias_mean>
		<bias_stddev>8e-07</bias_stddev>
	  </rate>
	  <accel>
		<mean>0</mean>
		<stddev>0.017</stddev>
		<bias_mean>0.1</bias_mean>
		<bias_stddev>0.001</bias_stddev>
	  </accel>
	</noise>
  </imu>
</sensor>
</gazebo>
</robot>